<?xml version="1.0"?>

<robot name="pioneer3dx"
	xmlns:sensor="http://playerstage.sourceforge.net/gazebo/xmlschema/#sensor"
	xmlns:controller="http://playerstage.sourceforge.net/gazebo/xmlschema/#controller"
	xmlns:interface="http://playerstage.sourceforge.net/gazebo/xmlschema/#interface"
	xmlns:xacro="http://ros.org/wiki/xacro">

    <xacro:include filename="$(find p2os_description)/urdf/pioneer3dx/pioneer3dx_wheel.xacro"/>

<!--	<property name='base_name' value='base_footprint'/> -->
	<property name='base_name' value='base_link'/>

<!-- Chassis -->
	<link name="${base_name}">
		<inertial>
			<mass value="3.5"/>
			<!--<origin xyz="-0.025 0 -0.223"/>-->
			<origin xyz="-0.05 0 0"/>
			<inertia ixx="1" ixy="0" ixz="0"
				 iyy="1" iyz="0"
				 izz="1"/>
		</inertial>
		<visual name="base_visual">
			<origin xyz="-0.045 0 0.148" rpy="0 0 0"/>
			<geometry name="pioneer_geom">
				<mesh filename="package://p2os_description/meshes/pioneer3dx/chassis.stl"/>
			</geometry>
			<material name="ChassisRed">
				<color rgba="0.851 0.0 0.0 1.0"/>
			</material>
		</visual>
		<collision>
			<origin xyz="-0.045 0 0.145" rpy="0 0 0"/>
				<geometry>
					<box size="0.35 0.25 0.14"/>
				</geometry>
		</collision>
	</link>

	<gazebo reference="${base_name}">
		<material value="Gazebo/Red"/>
	</gazebo>

<!-- Top -->
	<link name="top_plate">
		<inertial>
			<mass value="0.01"/>	
			<origin xyz="0 0 0"/>
			<inertia ixx="1" ixy="0" ixz="0"
				 iyy="1" iyz="0"
 				izz="1"/>
		</inertial>
		<visual name="base_visual">
			<origin xyz="0 0 0" rpy="0 0 0"/>
			<geometry name="top_geom">
				<mesh filename="package://p2os_description/meshes/pioneer3dx/top.stl"/>
			</geometry>

			<material name="TopBlack">
					<color rgba="0.038 0.038 0.038 1.0"/>
			</material>
		</visual>
		<collision>
			<origin xyz="0.0 0 0" rpy="0 0 0"/>
			<geometry name="pioneer_geom">
				<box size="0.45 0.38 0.01"/>
			</geometry>
		</collision>
	</link>
	<gazebo reference="top_plate">
		<material value="Gazebo/Black"/>
	</gazebo>


	<joint name="base_top_joint" type="fixed">
		<origin xyz="-0.045 0 0.234" rpy="0 0 0"/>
		<parent link="${base_name}"/>
		<child link="top_plate"/>
	</joint>



<!-- Swivel -->
	<link name="swivel">
		<inertial>
			<mass value="0.1"/>	
			<origin xyz="0 0 0"/>
			<inertia ixx="0.01" ixy="0" ixz="0"
				 iyy="0.01" iyz="0" izz="0.01"/>
  	 	</inertial>
	<visual name="base_visual">
		<origin xyz="0 0 0" rpy="0 0 0"/>
		<geometry name="pioneer_geom">
			<mesh filename="package://p2os_description/meshes/pioneer3dx/swivel.stl"/>
		</geometry>
		<material name="swivel">
			<color rgba="0.5 0.5 0.5 1"/>
		</material>
	</visual>
	<collision>
		<origin xyz="0 0 0" rpy="0 0 0"/>
		<geometry>
			<box size="0 0 0"/>
		</geometry>
	</collision>
	</link>
	<gazebo reference="swivel">
		<material value="Gazebo/Grey"/>
	</gazebo>


 	<joint name="base_swivel_joint" type="continuous">
		<origin xyz="-0.185 0 0.055" rpy="0 0 0"/>
		<axis xyz="0 0 1"/>
		<anchor xyz="0 0 0"/>
    <limit effort="100" velocity="100" k_velocity="0" />
    <joint_properties damping="0.0" friction="0.0" />
		<parent link="${base_name}"/>
		<child link="swivel"/>
	</joint>

    <transmission type="pr2_mechanism_model/SimpleTransmission" name="base_swivel_trans">
        <actuator name="base_swivel_motor" />
        <joint name="base_swivel_joint" />
        <mechanicalReduction>1.0</mechanicalReduction>
    </transmission>


<!-- Center Wheel + Hubcap -->
	<link name="center_hubcap">
		<inertial>
			<mass value="0.01"/>	
			<origin xyz="0 0 0"/>
			<inertia ixx="0.012411765597" ixy="-0.000711733678" ixz="0.00050272983"
				 iyy="0.015218160428" iyz="-0.000004273467" izz="0.011763977943"/>
  	 	</inertial>
	<visual name="base_visual">
		<origin xyz="0 0 0" rpy="0 0 0"/>
		<geometry name="pioneer_geom">
			<mesh filename="package://p2os_description/meshes/pioneer3dx/center_hubcap.stl"/>
		</geometry>
		<material name="swivel">
			<color rgba="0.5 0.5 0.5 1"/>
		</material>
	</visual>
	<collision>
		<origin xyz="0 0 0" rpy="0 0 0"/>
		<geometry>
			<box size="0 0 0"/>
		</geometry>
	</collision>
	</link>
	<gazebo reference="center_hubcap">
		<material value="Gazebo/Grey"/>
	</gazebo>

	<joint name="swivel_hubcap_joint" type="continuous">
		<origin xyz="-0.026 0 -0.016" rpy="0 0 0"/>
		<axis xyz="0 1 0"/>
		<anchor xyz="0 0 0"/>
    <limit effort="100" velocity="100" k_velocity="0" />
    <joint_properties damping="0.0" friction="0.0" />
	  <parent link="swivel"/>
		<child link="center_wheel"/>
	</joint>

    <transmission type="pr2_mechanism_model/SimpleTransmission" name="swivel_hubcap_trans">
        <actuator name="swivel_hubcap_motor" />
        <joint name="swivel_hubcap_joint" />
        <mechanicalReduction>1.0</mechanicalReduction>
    </transmission>

	<link name="center_wheel">
		<inertial>
			<mass value="0.1"/>	
			<origin xyz="0 0 0"/>
			<inertia ixx="0.012411765597" ixy="-0.000711733678" ixz="0.00050272983"
				 iyy="0.015218160428" iyz="-0.000004273467" izz="0.011763977943"/>
  	 	</inertial>
	<visual name="base_visual">
		<origin xyz="0 0 0" rpy="0 0 0"/>
		<geometry name="pioneer_geom">
			<mesh filename="package://p2os_description/meshes/pioneer3dx/center_wheel.stl"/>
		</geometry>
		<material name="WheelBlack">
			<color rgba="0.117 0.117 0.117 1"/>
		</material>
	</visual>
	<collision>
		<origin xyz="0 0 0" rpy="${-3.1415927/2.0} 0 0"/>
		<geometry>
			<!--<mesh filename="package://p2os_description/meshes/pioneer3dx/center_wheel.stl"/>-->
			<cylinder radius="0.0375" length="0.01"/>
		</geometry>
	</collision>
	</link>

	<joint name="center_wheel_joint" type="fixed">
		<origin xyz="-0.0035 0 -0.001" rpy="0 0 0"/>
		<parent link="center_wheel"/>
		<child link="center_hubcap"/>
	</joint>

	<gazebo reference="center_wheel">
		<material value="Gazebo/Black"/>
    <elem key="mu1" value="10.0" />
    <elem key="mu2" value="10.0" />
    <elem key="kp"  value="1000000.0" />
    <elem key="kd"  value="1.0" />
	</gazebo>


<xacro:p3dx_wheel suffix="left" parent="${base_name}" reflect="1"/>
<xacro:p3dx_wheel suffix="right" parent="${base_name}" reflect="-1"/>

<!-- Front Sonar -->
	<link name="front_sonar">
		<inertial>
			<mass value="0.0001"/>	
			<origin xyz="0 0 0"/>
			<inertia ixx="1" ixy="0" ixz="0"
				 iyy="1" iyz="0" izz="1"/>
		</inertial>
		<visual name="front_sonar_vis">
			<origin xyz="0 0 0" rpy="0 0 0"/>
			<geometry name="pioneer_geom">
				<mesh filename="package://p2os_description/meshes/pioneer3dx/front_sonar.stl"/>
			</geometry>
			<material name="SonarYellow">
				<color rgba="0.715 0.583 0.210 1.0"/>
			</material>
		</visual>
		<collision>
			<origin xyz="0 0 0" rpy="0 0 0"/>
			<geometry>
				<box size="0 0 0"/>
			</geometry>
		</collision>
	</link>

	<gazebo reference="front_sonar">
		<material value="Gazebo/Yellow"/>
	</gazebo>

	<joint name="base_front_joint" type="fixed">
		<origin xyz="0.109 0 0.209" rpy="0 0 0"/>
		<parent link="${base_name}"/>
		<child link="front_sonar"/>
	</joint>

  <gazebo>

	<!-- Robot kinematic properties -->
	<!-- These values were taken from the Pionner 3DX manual (and tech support)
		<wheelDiameter>0.1953</wheelDiameter>
   		<wheelSeparation>0.325</wheelSeparation>						-->
   	<!-- These values were taken from urdf and mesh files of the robot model
   		<wheelDiameter>0.19</wheelDiameter>
   		<wheelSeparation>0.33</wheelSeparation>							-->		

	<!-- Controller used to move the robot by sending commands to /cmd_vel topic -->

	<!-- p2os version
	<controller:differential_position2d name="controller1">
		<update>100</update>
		<leftJoint>base_left_wheel_joint</leftJoint>
		<rightJoint>base_right_wheel_joint</rightJoint>
		<wheelSeparation>0.158</wheelSeparation>
		<wheelDiameter>0.12</wheelDiameter>
		<torque>5</torque>
		<interface:position name="position_iface_0"/>
	</controller:differential_position2d> -->

	<!-- erratic version -->
    <controller:p2os_diffdrive_plugin name="differential_drive_controller" plugin="libp2os_diffdrive_plugin.so">
      <alwaysOn>true</alwaysOn>
      <update>100</update>
      <updateRate>100.0</updateRate>
      <leftJoint>base_right_wheel_joint</leftJoint>
      <rightJoint>base_left_wheel_joint</rightJoint>
		  <wheelDiameter>0.1953</wheelDiameter>
   		<wheelSeparation>0.325</wheelSeparation>
   		<torque>100</torque>
      <interface:position name="position_iface_0"/>
      <robotNamespace>/</robotNamespace>
      <topicName>cmd_vel</topicName>
    </controller:p2os_diffdrive_plugin>

	<!-- Not sure what this is for, but Erratic xacro file has it -->
    <canonicalBody>${base_name}</canonicalBody>

    <controller:gazebo_ros_p3d name="p3d_base_controller" plugin="libgazebo_ros_p3d.so">
      <alwaysOn>true</alwaysOn>
      <updateRate>100.0</updateRate>
      <bodyName>${base_name}</bodyName>
      <topicName>base_pose_ground_truth</topicName>
      <gaussianNoise>0.01</gaussianNoise>
      <frameName>map</frameName>
      <xyzOffsets>0 0 0</xyzOffsets> <!-- initialize odometry for fake localization-->
      <rpyOffsets>0 0 0</rpyOffsets>
      <interface:position name="p3d_base_position"/>
    </controller:gazebo_ros_p3d>

    <!-- this publishes empty joint_states due to no transmission, but
         triggering robot_state_puublisher to publish tf between fixed joints in erratic,
         (e.g. base_laser_link for the base_scan frame) -->
    <controller:gazebo_ros_controller_manager name="gazebo_ros_controller_manager" plugin="libgazebo_ros_controller_manager.so">
      <alwaysOn>true</alwaysOn>
      <updateRate>1000.0</updateRate>
      <interface:audio name="gazebo_ros_controller_manager_dummy_iface" />
    </controller:gazebo_ros_controller_manager>
  </gazebo>

</robot>
